Workbook

Sheet customer_data_removed_duplicate
A1: user_id | B1: country | C1: age | D1: gender | E1: subscription_type | F1: avg_listening_hours_per_week | G1: total_songs_played | H1: skip_rate | I1: satisfaction_score | J1: churned | K1: monthly_fee | L1: join_date | M1: join_date_UK | N1: Year of Join
A2: U1201 | B2: South Africa | C2: 41 | E2: Family | F2: 3 | G2: 529 | H2: 0.2 | J2: 0 | K2: 7.99 | L2: 08/08/2023 | M2: 45146 | N2: =YEAR(Raw_Data[[#This Row],[join_date_UK]]) -> 2023
A3: U1257 | B3: India | C3: 15 | E3: Family | F3: 0.3 | G3: 503 | H3: 0.3 | J3: 0 | L3: 03/30/2024 | M3: 45381 | N3: =YEAR(Raw_Data[[#This Row],[join_date_UK]]) -> 2024
A4: U1558 | B4: Nigeria | C4: 49 | D4: Female | E4: Family | F4: 5.6 | G4: 497 | H4: 0.15 | J4: 1 | K4: 7.99 | L4: 07/01/2023 | M4: 45108 | N4: =YEAR(Raw_Data[[#This Row],[join_date_UK]]) -> 2023
A5: U1693 | B5: Ghana | C5: 49 | D5: Female | E5: Family | F5: 8.8 | G5: 509 | H5: 0.1 | J5: 1 | K5: 9.99 | L5: 09/08/2024 | M5: 45543 | N5: =YEAR(Raw_Data[[#This Row],[join_date_UK]]) -> 2024
A6: U1486 | B6: Kenya | C6: 25 | D6: Other | E6: Family | F6: 6.3 | G6: 498 | H6: 0.3 | J6: 1 | K6: 12.99 | L6: 14/09/2023 | M6: 45183 | N6: =YEAR(Raw_Data[[#This Row],[join_date_UK]]) -> 2023
A7: U1345 | B7: Nepal | C7: 27 | D7: Male | E7: Family | F7: 6.2 | G7: 511 | H7: 0.2 | J7: 1 | L7: 28/03/2024 | M7: 45379 | N7: =YEAR(Raw_Data[[#This Row],[join_date_UK]]) -> 2024
A8: U1203 | B8: Nepal | C8: 62 | E8: Family | F8: 17.2 | G8: 508 | H8: 0.1 | J8: 1 | K8: 9.99 | L8: 12/08/2023 | M8: 45268 | N8: =YEAR(Raw_Data[[#This Row],[join_date_UK]]) -> 2023
A9: U1641 | B9: United Kingdom | C9: 62 | D9: Female | E9: Family | F9: 5.6 | G9: 484 | H9: 0.2 | J9: 0 | K9: 9.99 | L9: 08/12/2022 | M9: 44785 | N9: =YEAR(Raw_Data[[#This Row],[join_date_UK]]) -> 2022
A10: U1569 | B10: India | C10: 59 | D10: Male | E10: Family | F10: 13.8 | G10: 492 | H10: 0.05 | J10: 0 | K10: 5 | L10: 16/06/2023 | M10: 45093 | N10: =YEAR(Raw_Data[[#This Row],[join_date_UK]]) -> 2023
A11: U1694 | B11: USA | C11: 33 | D11: Female | E11: Family | F11: 14.8 | G11: 488 | H11: 0.3 | J11: 0 | K11: 9.99 | L11: 27/07/2024 | M11: 45500 | N11: =YEAR(Raw_Data[[#This Row],[join_date_UK]]) -> 2024
A12: U1225 | B12: Nepal | C12: 39 | D12: Male | E12: Family | F12: 8.5 | G12: 486 | H12: 0.15 | J12: 1 | L12: 27/06/2022 | M12: 44739 | N12: =YEAR(Raw_Data[[#This Row],[join_date_UK]]) -> 2022
A13: U1369 | B13: Ghana | C13: 48 | D13: Other | E13: Family | F13: 9 | G13: 477 | H13: 0.1 | J13: 0 | L13: 04/23/2022 | M13: 44674 | N13: =YEAR(Raw_Data[[#This Row],[join_date_UK]]) -> 2022
A14: U1637 | B14: United Kingdom | C14: 13 | D14: Male | E14: Family | F14: 11.3 | G14: 493 | H14: 0.2 | J14: 0 | K14: 5 | L14: 11/05/2022 | M14: 44870 | N14: =YEAR(Raw_Data[[#This Row],[join_date_UK]]) -> 2022
A15: U1592 | B15: USA | C15: 36 | D15: Male | E15: Free | F15: 0.9 | G15: 509 | H15: 0.3 | J15: 0 | K15: 0 | L15: 09/10/2022 | M15: 44814 | N15: =YEAR(Raw_Data[[#This Row],[join_date_UK]]) -> 2022
A16: U1548 | B16: Nigeria | C16: 63 | D16: Other | E16: Free | F16: 13.9 | G16: 467 | H16: 0.15 | J16: 0 | K16: 0 | L16: 03/20/2024 | M16: 45371 | N16: =YEAR(Raw_Data[[#This Row],[join_date_UK]]) -> 2024
A17: U1272 | B17: United Kingdom | C17: 22 | D17: Female | E17: Free | F17: 4.4 | G17: 499 | H17: 0.2 | J17: 0 | K17: 0 | L17: 05/26/2022 | M17: 44707 | N17: =YEAR(Raw_Data[[#This Row],[join_date_UK]]) -> 2022
A18: U1026 | B18: United Kingdom | C18: 23 | D18: Female | E18: Free | F18: 7.5 | G18: 497 | H18: 0.25 | J18: 0 | K18: 0 | L18: 08/04/2024 | M18: 45508 | N18: =YEAR(Raw_Data[[#This Row],[join_date_UK]]) -> 2024
A19: U1636 | B19: India | C19: 30 | E19: Free | F19: 17.9 | G19: 496 | H19: 0.2 | J19: 0 | K19: 0 | L19: 07/07/2024 | M19: 45480 | N19: =YEAR(Raw_Data[[#This Row],[join_date_UK]]) -> 2024
A20: U1552 | B20: United Kingdom | C20: 53 | D20: Other | E20: Free | F20: 10.7 | G20: 510 | H20: 0.2 | J20: 0 | K20: 0 | L20: 12/30/2022 | M20: 44925 | N20: =YEAR(Raw_Data[[#This Row],[join_date_UK]]) -> 2022
A21: U1155 | B21: India | C21: 39 | D21: Female | E21: Premium | F21: 0.3 | G21: 510 | H21: 0.1 | J21: 1 | K21: 9.99 | L21: 07/03/2024 | M21: 45476 | N21: =YEAR(Raw_Data[[#This Row],[join_date_UK]]) -> 2024
A22: U1657 | B22: India | C22: 22 | D22: Male | E22: Premium | F22: 3.6 | G22: 486 | H22: 0.1 | J22: 1 | L22: 28/07/2022 | M22: 44770 | N22: =YEAR(Raw_Data[[#This Row],[join_date_UK]]) -> 2022
A23: U1436 | B23: India | C23: 26 | D23: Female | E23: Premium | F23: 16.9 | G23: 490 | H23: 0.1 | J23: 0 | K23: 9.99 | L23: 14/05/2024 | M23: 45426 | N23: =YEAR(Raw_Data[[#This Row],[join_date_UK]]) -> 2024
A24: U1309 | B24: Brazil | C24: 18 | D24: Female | E24: Premium | F24: 12.8 | G24: 476 | H24: 0.3 | J24: 1 | K24: 9.99 | L24: 09/04/2023 | M24: 45173 | N24: =YEAR(Raw_Data[[#This Row],[join_date_UK]]) -> 2023
A25: U1215 | B25: United Kingdom | C25: 17 | D25: Male | E25: Premium | F25: 11.7 | G25: 495 | H25: 0.1 | J25: 1 | K25: 9.99 | L25: 27/08/2024 | M25: 45531 | N25: =YEAR(Raw_Data[[#This Row],[join_date_UK]]) -> 2024
A26: U1600 | B26: United Kingdom | C26: 41 | D26: Female | E26: Premium | F26: 8.7 | G26: 483 | H26: 0.05 | J26: 0 | K26: 9.99 | L26: 02/07/2024 | M26: 45329 | N26: =YEAR(Raw_Data[[#This Row],[join_date_UK]]) -> 2024
A27: U1141 | B27: United Kingdom | C27: 33 | D27: Male | E27: Premium | F27: 16.1 | G27: 505 | H27: 0.05 | J27: 1 | K27: 7.99 | L27: 31/05/2023 | M27: 45077 | N27: =YEAR(Raw_Data[[#This Row],[join_date_UK]]) -> 2023
A28: U1000 | B28: Kenya | C28: 18 | D28: Male | E28: Premium | F28: 6.3 | G28: 485 | H28: 0.05 | J28: 0 | K28: 7.99 | L28: 25/02/2023 | M28: 44982 | N28: =YEAR(Raw_Data[[#This Row],[join_date_UK]]) -> 2023
A29: U1085 | B29: Kenya | C29: 45 | D29: Male | E29: Premium | F29: 6 | G29: 487 | H29: 0.3 | J29: 0 | K29: 7.99 | L29: 10/07/2023 | M29: 45206 | N29: =YEAR(Raw_Data[[#This Row],[join_date_UK]]) -> 2023
A30: U1661 | B30: South Africa | C30: 45 | D30: Male | E30: Premium | F30: 11.2 | G30: 512 | H30: 0.05 | J30: 0 | K30: 5 | L30: 24/05/2024 | M30: 45436 | N30: =YEAR(Raw_Data[[#This Row],[join_date_UK]]) -> 2024
A31: U1042 | B31: Ghana | C31: 40 | D31: Male | E31: Premium | F31: 8.1 | G31: 484 | H31: 0.2 | J31: 0 | K31: 7.99 | L31: 05/06/2023 | M31: 45052 | N31: =YEAR(Raw_Data[[#This Row],[join_date_UK]]) -> 2023
A32: U1579 | B32: India | C32: 38 | D32: Female | E32: Premium | F32: 13.7 | G32: 525 | H32: 0.15 | J32: 0 | K32: 7.99 | L32: 23/05/2022 | M32: 44704 | N32: =YEAR(Raw_Data[[#This Row],[join_date_UK]]) -> 2022
A33: U1075 | B33: Nigeria | C33: 59 | D33: Female | E33: Premium | F33: 4.1 | G33: 506 | H33: 0.25 | J33: 1 | K33: 9.99 | L33: 08/03/2022 | M33: 44776 | N33: =YEAR(Raw_Data[[#This Row],[join_date_UK]]) -> 2022
A34: U1439 | B34: Nepal | C34: 50 | D34: Female | E34: Student | F34: 10.6 | G34: 490 | H34: 0.1 | J34: 1 | K34: 9.99 | L34: 16/11/2022 | M34: 44881 | N34: =YEAR(Raw_Data[[#This Row],[join_date_UK]]) -> 2022
A35: U1076 | B35: India | C35: 61 | D35: Male | E35: Student | F35: 16 | G35: 498 | H35: 0.05 | J35: 0 | L35: 15/02/2023 | M35: 44972 | N35: =YEAR(Raw_Data[[#This Row],[join_date_UK]]) -> 2023
A36: U1499 | B36: United Kingdom | C36: 16 | D36: Male | E36: Student | F36: 11.2 | G36: 485 | H36: 0.15 | J36: 0 | K36: 12.99 | L36: 05/30/2024 | M36: 45442 | N36: =YEAR(Raw_Data[[#This Row],[join_date_UK]]) -> 2024
A37: U1521 | B37: Nigeria | C37: 59 | D37: Female | E37: Student | F37: 0.3 | G37: 506 | H37: 0.1 | J37: 0 | K37: 7.99 | L37: 09/03/2023 | M37: 45172 | N37: =YEAR(Raw_Data[[#This Row],[join_date_UK]]) -> 2023
A38: U1344 | B38: Nepal | C38: 14 | D38: Male | E38: Student | F38: 15.8 | G38: 501 | H38: 0.25 | J38: 0 | K38: 9.99 | L38: 15/06/2024 | M38: 45458 | N38: =YEAR(Raw_Data[[#This Row],[join_date_UK]]) -> 2024
A39: U1622 | B39: Ghana | C39: 42 | D39: Female | E39: Student | F39: 4.5 | G39: 520 | H39: 0.15 | J39: 1 | K39: 12.99 | L39: 09/04/2023 | M39: 45173 | N39: =YEAR(Raw_Data[[#This Row],[join_date_UK]]) -> 2023
A40: U1475 | B40: India | C40: 49 | D40: Male | E40: Student | F40: 13.9 | G40: 480 | H40: 0.3 | J40: 0 | K40: 9.99 | L40: 03/12/2024 | M40: 45363 | N40: =YEAR(Raw_Data[[#This Row],[join_date_UK]]) -> 2024
...

Sheet Churn Analysis
A1: Satisfaction | B1: Churn | D1: Country | E1: Subscriber Number | F1: Churn Rate | K1: Age Range | L1: Subscriber Number | M1: Churn Rate | S1: Sub Type | T1: Av Churn | W1: Total Songs | X1: Skip Rate | Y1: Average Listening Hours | Z1: Churn Rate | AD1: Total Songs | AE1: Skip Rate | AF1: Average Listening Hours | AG1: Churn Rate | AK1: Year | AL1: Average Churn
A2: 1 | B2: =AVERAGEIF(Raw_Data[satisfaction_score],'Churn Analysis'!A2,Raw_Data[churned]) -> 0.26027397 | D2: {=_xlfn.UNIQUE(Raw_Data[country])} -> South Africa | E2: =COUNTIF(Raw_Data[country],'Churn Analysis'!D2) -> 55 | F2: =AVERAGEIFS(Raw_Data[churned],Raw_Data[country],'Churn Analysis'!D2,Raw_Data[churned],"<>"&"") -> 0.27272727 | K2: under 18 | L2: 74 | M2: 0.35135135 | S2: Family | T2: =AVERAGEIF(Raw_Data[subscription_type],'Churn Analysis'!S2,Raw_Data[churned]) -> 0.33014354 | W2: Up to 450 | X2: =AVERAGEIF(Raw_Data[total_songs_played],"<=450",Raw_Data[skip_rate]) -> 0.19285714 | Y2: =AVERAGEIFS(Raw_Data[avg_listening_hours_per_week],Raw_Data[total_songs_played],"<=450") -> 7.2142857 | Z2: =AVERAGEIFS(Raw_Data[churned],Raw_Data[total_songs_played],"<=450") -> 0.14285714 | AD2: Up to 450 | AE2: =AVERAGEIFS(Raw_Data[skip_rate],Raw_Data[total_songs_played],"<451",Raw_Data[subscription_type],"Free") -> #DIV/0! | AF2: =AVERAGEIFS(Raw_Data[avg_listening_hours_per_week],Raw_Data[total_songs_played],"<=450",Raw_Data[subscription_type],"Free") -> #DIV/0! | AG2: =AVERAGEIFS(Raw_Data[churned],Raw_Data[total_songs_played],"<=450",Raw_Data[subscription_type],"Free") -> #DIV/0! | AK2: 2022 | AL2: =AVERAGEIFS(Raw_Data[churned],Raw_Data[Year of Join],AK2) -> 0.3297491
A3: 2 | B3: =AVERAGEIF(Raw_Data[satisfaction_score],'Churn Analysis'!A3,Raw_Data[churned]) -> 0.36792453 | D3: India | E3: =COUNTIF(Raw_Data[country],'Churn Analysis'!D3) -> 114 | F3: =AVERAGEIFS(Raw_Data[churned],Raw_Data[country],'Churn Analysis'!D3,Raw_Data[churned],"<>"&"") -> 0.24561404 | K3: 18 - 24 | L3: 94 | M3: 0.32432432 | S3: Free | T3: =AVERAGEIF(Raw_Data[subscription_type],'Churn Analysis'!S3,Raw_Data[churned]) -> 0.25490196 | W3: 451 - 475 | X3: =AVERAGEIFS(Raw_Data[skip_rate],Raw_Data[total_songs_played],">450",Raw_Data[total_songs_played],"<=475") -> 0.17444444 | Y3: =AVERAGEIFS(Raw_Data[avg_listening_hours_per_week],Raw_Data[total_songs_played],">=451",Raw_Data[total_songs_played],"<=475") -> 10.525556 | Z3: =AVERAGEIFS(Raw_Data[churned],Raw_Data[total_songs_played],">=451",Raw_Data[total_songs_played],"<=475") -> 0.25555556 | AD3: 451 - 475 | AE3: =AVERAGEIFS(Raw_Data[skip_rate],Raw_Data[total_songs_played],">450",Raw_Data[total_songs_played],"<=475",Raw_Data[subscription_type],"Free") -> 0.195 | AF3: =AVERAGEIFS(Raw_Data[avg_listening_hours_per_week],Raw_Data[total_songs_played],">=451",Raw_Data[total_songs_played],"<=475",Raw_Data[subscription_type],"Free") -> 7.63 | AG3: =AVERAGEIFS(Raw_Data[churned],Raw_Data[total_songs_played],">=451",Raw_Data[total_songs_played],"<=475",Raw_Data[subscription_type],"Free") -> 0.1 | AK3: 2023 | AL3: =AVERAGEIFS(Raw_Data[churned],Raw_Data[Year of Join],AK3) -> 0.3040293
A4: 3 | B4: =AVERAGEIF(Raw_Data[satisfaction_score],'Churn Analysis'!A4,Raw_Data[churned]) -> 0.2489083 | D4: Nigeria | E4: =COUNTIF(Raw_Data[country],'Churn Analysis'!D4) -> 65 | F4: =AVERAGEIFS(Raw_Data[churned],Raw_Data[country],'Churn Analysis'!D4,Raw_Data[churned],"<>"&"") -> 0.38461538 | K4: 25 - 34 | L4: 120 | M4: 0.28985507 | S4: Premium | T4: =AVERAGEIF(Raw_Data[subscription_type],'Churn Analysis'!S4,Raw_Data[churned]) -> 0.31182796 | W4: 476 - 500 | X4: =AVERAGEIFS(Raw_Data[skip_rate],Raw_Data[total_songs_played],">=476",Raw_Data[total_songs_played],"<=500") -> 0.17314488 | Y4: =AVERAGEIFS(Raw_Data[avg_listening_hours_per_week],Raw_Data[total_songs_played],">=476",Raw_Data[total_songs_played],"<=500") -> 10.198233 | Z4: =AVERAGEIFS(Raw_Data[churned],Raw_Data[total_songs_played],">=476",Raw_Data[total_songs_played],"<=500") -> 0.28268551 | AD4: 476 - 500 | AE4: =AVERAGEIFS(Raw_Data[skip_rate],Raw_Data[total_songs_played],">=476",Raw_Data[total_songs_played],"<=500",Raw_Data[subscription_type],"Free") -> 0.18953488 | AF4: =AVERAGEIFS(Raw_Data[avg_listening_hours_per_week],Raw_Data[total_songs_played],">=476",Raw_Data[total_songs_played],"<=500",Raw_Data[subscription_type],"Free") -> 9.5325581 | AG4: =AVERAGEIFS(Raw_Data[churned],Raw_Data[total_songs_played],">=476",Raw_Data[total_songs_played],"<=500",Raw_Data[subscription_type],"Free") -> 0.23255814 | AK4: 2024 | AL4: =AVERAGEIFS(Raw_Data[churned],Raw_Data[Year of Join],AK4) -> 0.26351351
A5: 4 | B5: =AVERAGEIF(Raw_Data[satisfaction_score],'Churn Analysis'!A5,Raw_Data[churned]) -> 0.34210526 | D5: Ghana | E5: =COUNTIF(Raw_Data[country],'Churn Analysis'!D5) -> 56 | F5: =AVERAGEIFS(Raw_Data[churned],Raw_Data[country],'Churn Analysis'!D5,Raw_Data[churned],"<>"&"") -> 0.375 | K5: 35 - 44 | L5: 143 | M5: 0.2972973 | S5: Student | T5: =AVERAGEIF(Raw_Data[subscription_type],'Churn Analysis'!S5,Raw_Data[churned]) -> 0.30049261 | W5: 501 - 525 | X5: =AVERAGEIFS(Raw_Data[skip_rate],Raw_Data[total_songs_played],">=501",Raw_Data[total_songs_played],"<=525") -> 0.16554622 | Y5: =AVERAGEIFS(Raw_Data[avg_listening_hours_per_week],Raw_Data[total_songs_played],">=501",Raw_Data[total_songs_played],"<=525") -> 9.6432773 | Z5: =AVERAGEIFS(Raw_Data[churned],Raw_Data[total_songs_played],">=501",Raw_Data[total_songs_played],"<=525") -> 0.36134454 | AD5: 501 - 525 | AE5: =AVERAGEIFS(Raw_Data[skip_rate],Raw_Data[total_songs_played],">=501",Raw_Data[total_songs_played],"<=525",Raw_Data[subscription_type],"Free") -> 0.17285714 | AF5: =AVERAGEIFS(Raw_Data[avg_listening_hours_per_week],Raw_Data[total_songs_played],">=501",Raw_Data[total_songs_played],"<=525",Raw_Data[subscription_type],"Free") -> 11.074286 | AG5: =AVERAGEIFS(Raw_Data[churned],Raw_Data[total_songs_played],">=501",Raw_Data[total_songs_played],"<=525",Raw_Data[subscription_type],"Free") -> 0.31428571
A6: 5 | B6: =AVERAGEIF(Raw_Data[satisfaction_score],'Churn Analysis'!A6,Raw_Data[churned]) -> 0.32291667 | D6: Kenya | E6: =COUNTIF(Raw_Data[country],'Churn Analysis'!D6) -> 65 | F6: =AVERAGEIFS(Raw_Data[churned],Raw_Data[country],'Churn Analysis'!D6,Raw_Data[churned],"<>"&"") -> 0.32307692 | K6: 45 - 54 | L6: 130 | M6: 0.3 | W6: 526 - 550 | X6: =AVERAGEIFS(Raw_Data[skip_rate],Raw_Data[total_songs_played],">=526",Raw_Data[total_songs_played],"<=550") -> 0.14057971 | Y6: =AVERAGEIFS(Raw_Data[avg_listening_hours_per_week],Raw_Data[total_songs_played],">=526",Raw_Data[total_songs_played],"<=550") -> 10.346377 | Z6: =AVERAGEIFS(Raw_Data[churned],Raw_Data[total_songs_played],">=526",Raw_Data[total_songs_played],"<=550") -> 0.31884058 | AD6: 526 - 550 | AE6: =AVERAGEIFS(Raw_Data[skip_rate],Raw_Data[total_songs_played],">=526",Raw_Data[total_songs_played],"<=550",Raw_Data[subscription_type],"Free") -> 0.14583333 | AF6: =AVERAGEIFS(Raw_Data[avg_listening_hours_per_week],Raw_Data[total_songs_played],">=526",Raw_Data[total_songs_played],"<=550",Raw_Data[subscription_type],"Free") -> 9.8333333 | AG6: =AVERAGEIFS(Raw_Data[churned],Raw_Data[total_songs_played],">=526",Raw_Data[total_songs_played],"<=550",Raw_Data[subscription_type],"Free") -> 0.33333333 | AK6: Good short term retention. Issues holding people for the longer term.
D7: Nepal | E7: =COUNTIF(Raw_Data[country],'Churn Analysis'!D7) -> 46 | F7: =AVERAGEIFS(Raw_Data[churned],Raw_Data[country],'Churn Analysis'!D7,Raw_Data[churned],"<>"&"") -> 0.26086957 | K7: 55 - 64 | L7: 139 | M7: 0.31884058 | W7: 551 - 575 | X7: =AVERAGEIFS(Raw_Data[skip_rate],Raw_Data[total_songs_played],">=551",Raw_Data[total_songs_played],"<=575") -> 0.18846154 | Y7: =AVERAGEIFS(Raw_Data[avg_listening_hours_per_week],Raw_Data[total_songs_played],">=551",Raw_Data[total_songs_played],"<=575") -> 9.6 | Z7: =AVERAGEIFS(Raw_Data[churned],Raw_Data[total_songs_played],">=551",Raw_Data[total_songs_played],"<=575") -> 0.15384615 | AD7: 551 - 575 | AE7: =AVERAGEIFS(Raw_Data[skip_rate],Raw_Data[total_songs_played],">=551",Raw_Data[total_songs_played],"<=575",Raw_Data[subscription_type],"Free") -> 0.225 | AF7: =AVERAGEIFS(Raw_Data[avg_listening_hours_per_week],Raw_Data[total_songs_played],">=551",Raw_Data[total_songs_played],"<=575",Raw_Data[subscription_type],"Free") -> 9.8 | AG7: =AVERAGEIFS(Raw_Data[churned],Raw_Data[total_songs_played],">=551",Raw_Data[total_songs_played],"<=575",Raw_Data[subscription_type],"Free") -> 0
D8: United Kingdom | E8: =COUNTIF(Raw_Data[country],'Churn Analysis'!D8) -> 183 | F8: =AVERAGEIFS(Raw_Data[churned],Raw_Data[country],'Churn Analysis'!D8,Raw_Data[churned],"<>"&"") -> 0.32240437 | S8: 1. Price potentially a main factor
D9: USA | E9: =COUNTIF(Raw_Data[country],'Churn Analysis'!D9) -> 76 | F9: =AVERAGEIFS(Raw_Data[churned],Raw_Data[country],'Churn Analysis'!D9,Raw_Data[churned],"<>"&"") -> 0.23684211
D10: Brazil | E10: =COUNTIF(Raw_Data[country],'Churn Analysis'!D10) -> 40 | F10: =AVERAGEIFS(Raw_Data[churned],Raw_Data[country],'Churn Analysis'!D10,Raw_Data[churned],"<>"&"") -> 0.375
A12: Recommendation: 1. No strong correlation between satisfaction and churn. Recommend reviewing feedback questionaire and improving satisfaction calculation.
W24: 1. No strong correlation between skip and churn measured against number of songs played. Algorythm most optimalat 526 - 550 listens, and then takes a downturn in efficiency (skip rate). Recommendation: Examine this anomaly. 2. Most likely to lose listerners between 501 - 550 listens, after which loyalty significantly solidifies. Need to encentivise listeners to stay throught this period.
D27: Recommendation: 1. Lowest churn in Nepal, India and USA. 2. Highest churn in Brazil, Ghana, Nigeria. 3. Concentrate on increasing membership in core markets: India, USA. 4. Prioritise reducing UK churn & Brazil due to high spend per customer.
K28: Recommendation: 1. Core Market 35 -64. 2. Minimise churn within core market. Further study into type of music most listened to with fewest skips and algorythnm recommendation optimisation.

Sheet Age Categories
B1: Age | C1: N Users | D1: Churned | F1: Age Range | G1: N Users | H1: Churn Rate
A2: under 18 | B2: 13 | C2: =COUNTIF(Raw_Data[age],'Age Categories'!B2) -> 17 | D2: =SUMIF(Raw_Data[age],'Age Categories'!B2,Raw_Data[churned]) -> 6 | F2: under 18 | G2: =SUMIF(A:A,F2,C:C) -> 74 | H2: =SUM(D2:D6)/SUM(C2:C6) -> 0.35135135
A3: under 18 | B3: 14 | C3: =COUNTIF(Raw_Data[age],'Age Categories'!B3) -> 13 | D3: =SUMIF(Raw_Data[age],'Age Categories'!B3,Raw_Data[churned]) -> 4 | F3: 18 - 24 | G3: =SUMIF(A:A,F3,C:C) -> 94 | H3: =SUM(D3:D7)/SUM(C3:C7) -> 0.32432432
A4: under 18 | B4: 15 | C4: =COUNTIF(Raw_Data[age],'Age Categories'!B4) -> 13 | D4: =SUMIF(Raw_Data[age],'Age Categories'!B4,Raw_Data[churned]) -> 4 | F4: 25 - 34 | G4: =SUMIF(A:A,F4,C:C) -> 120 | H4: =SUM(D4:D8)/SUM(C4:C8) -> 0.28985507
A5: under 18 | B5: 16 | C5: =COUNTIF(Raw_Data[age],'Age Categories'!B5) -> 14 | D5: =SUMIF(Raw_Data[age],'Age Categories'!B5,Raw_Data[churned]) -> 5 | F5: 35 - 44 | G5: =SUMIF(A:A,F5,C:C) -> 143 | H5: =SUM(D5:D9)/SUM(C5:C9) -> 0.2972973
A6: under 18 | B6: 17 | C6: =COUNTIF(Raw_Data[age],'Age Categories'!B6) -> 17 | D6: =SUMIF(Raw_Data[age],'Age Categories'!B6,Raw_Data[churned]) -> 7 | F6: 45 - 54 | G6: =SUMIF(A:A,F6,C:C) -> 130 | H6: =SUM(D6:D10)/SUM(C6:C10) -> 0.3
A7: 18 - 24 | B7: 18 | C7: =COUNTIF(Raw_Data[age],'Age Categories'!B7) -> 17 | D7: =SUMIF(Raw_Data[age],'Age Categories'!B7,Raw_Data[churned]) -> 4 | F7: 55 - 64 | G7: =SUMIF(A:A,F7,C:C) -> 139 | H7: =SUM(D7:D11)/SUM(C7:C11) -> 0.31884058
A8: 18 - 24 | B8: 19 | C8: =COUNTIF(Raw_Data[age],'Age Categories'!B8) -> 8 | D8: =SUMIF(Raw_Data[age],'Age Categories'!B8,Raw_Data[churned]) -> 0
A9: 18 - 24 | B9: 20 | C9: =COUNTIF(Raw_Data[age],'Age Categories'!B9) -> 18 | D9: =SUMIF(Raw_Data[age],'Age Categories'!B9,Raw_Data[churned]) -> 6
A10: 18 - 24 | B10: 21 | C10: =COUNTIF(Raw_Data[age],'Age Categories'!B10) -> 10 | D10: =SUMIF(Raw_Data[age],'Age Categories'!B10,Raw_Data[churned]) -> 4
A11: 18 - 24 | B11: 22 | C11: =COUNTIF(Raw_Data[age],'Age Categories'!B11) -> 16 | D11: =SUMIF(Raw_Data[age],'Age Categories'!B11,Raw_Data[churned]) -> 8
A12: 18 - 24 | B12: 23 | C12: =COUNTIF(Raw_Data[age],'Age Categories'!B12) -> 16 | D12: =SUMIF(Raw_Data[age],'Age Categories'!B12,Raw_Data[churned]) -> 7
A13: 18 - 24 | B13: 24 | C13: =COUNTIF(Raw_Data[age],'Age Categories'!B13) -> 9 | D13: =SUMIF(Raw_Data[age],'Age Categories'!B13,Raw_Data[churned]) -> 3
A14: 25 - 34 | B14: 25 | C14: =COUNTIF(Raw_Data[age],'Age Categories'!B14) -> 11 | D14: =SUMIF(Raw_Data[age],'Age Categories'!B14,Raw_Data[churned]) -> 2
A15: 25 - 34 | B15: 26 | C15: =COUNTIF(Raw_Data[age],'Age Categories'!B15) -> 17 | D15: =SUMIF(Raw_Data[age],'Age Categories'!B15,Raw_Data[churned]) -> 5
A16: 25 - 34 | B16: 27 | C16: =COUNTIF(Raw_Data[age],'Age Categories'!B16) -> 13 | D16: =SUMIF(Raw_Data[age],'Age Categories'!B16,Raw_Data[churned]) -> 5
A17: 25 - 34 | B17: 28 | C17: =COUNTIF(Raw_Data[age],'Age Categories'!B17) -> 7 | D17: =SUMIF(Raw_Data[age],'Age Categories'!B17,Raw_Data[churned]) -> 3
A18: 25 - 34 | B18: 29 | C18: =COUNTIF(Raw_Data[age],'Age Categories'!B18) -> 14 | D18: =SUMIF(Raw_Data[age],'Age Categories'!B18,Raw_Data[churned]) -> 2
A19: 25 - 34 | B19: 30 | C19: =COUNTIF(Raw_Data[age],'Age Categories'!B19) -> 12 | D19: =SUMIF(Raw_Data[age],'Age Categories'!B19,Raw_Data[churned]) -> 3
... A53: 55 - 64 | B53: 64 | C53: =COUNTIF(Raw_Data[age],'Age Categories'!B53) -> 10 | D53: =SUMIF(Raw_Data[age],'Age Categories'!B53,Raw_Data[churned]) -> 3

Sheet Pivot Table
A3: Row Labels | B3: Sum of avg_listening_hours_per_week | C3: Sum of total_songs_played | D3: Sum of monthly_fee | H3: Country
A4: Brazil | B4: 468.8 | C4: 20240 | D4: 282.73 | H4: Brazil | I4: Ghana | J4: India | K4: Kenya | L4: Nepal | M4: Nigeria | N4: South Africa | O4: United Kingdom | P4: USA
A5: Family | B5: 135.8 | C5: 7147 | D5: 107.88 | G5: Satisfaction Score
A6: Free | B6: 26.1 | C6: 1547 | D6: 0 | G6: Null | H6: =COUNTIFS(Raw_Data[country],"Brazil",Raw_Data[satisfaction_score], "") -> 1 | I6: =COUNTIFS(Raw_Data[country],"Ghana",Raw_Data[satisfaction_score], "") -> 4 | J6: =COUNTIFS(Raw_Data[country],"India",Raw_Data[satisfaction_score], "") -> 10 | K6: =COUNTIFS(Raw_Data[country],"Kenya",Raw_Data[satisfaction_score], "") -> 3 | L6: =COUNTIFS(Raw_Data[country],"Nepal",Raw_Data[satisfaction_score], "") -> 5 | M6: =COUNTIFS(Raw_Data[country],"Nigeria",Raw_Data[satisfaction_score], "") -> 5 | N6: =COUNTIFS(Raw_Data[country],"South Africa",Raw_Data[satisfaction_score], "") -> 2 | O6: =COUNTIFS(Raw_Data[country],"United Kingdom",Raw_Data[satisfaction_score], "") -> 12 | P6: =COUNTIFS(Raw_Data[country],"USA",Raw_Data[satisfaction_score], "") -> 2
A7: Premium | B7: 102 | C7: 4040 | D7: 60.95 | G7: 1 | H7: =COUNTIFS(Raw_Data[country],"Brazil",Raw_Data[satisfaction_score],1) -> 2 | I7: =COUNTIFS(Raw_Data[country],"Ghana",Raw_Data[satisfaction_score], 1) -> 4 | J7: =COUNTIFS(Raw_Data[country],"India",Raw_Data[satisfaction_score], 1) -> 11 | K7: =COUNTIFS(Raw_Data[country],"Kenya",Raw_Data[satisfaction_score], 1) -> 7 | L7: =COUNTIFS(Raw_Data[country],"Nepal",Raw_Data[satisfaction_score], 1) -> 5 | M7: =COUNTIFS(Raw_Data[country],"Nigeria",Raw_Data[satisfaction_score], 1) -> 6 | N7: =COUNTIFS(Raw_Data[country],"South Africa",Raw_Data[satisfaction_score], 1) -> 9 | O7: =COUNTIFS(Raw_Data[country],"United Kingdom",Raw_Data[satisfaction_score], 1) -> 18 | P7: =COUNTIFS(Raw_Data[country],"USA",Raw_Data[satisfaction_score], 1) -> 11
A8: Student | B8: 204.9 | C8: 7506 | D8: 113.9 | G8: 2 | H8: =COUNTIFS(Raw_Data[country],"Brazil",Raw_Data[satisfaction_score],2) -> 9 | I8: =COUNTIFS(Raw_Data[country],"Ghana",Raw_Data[satisfaction_score], 2) -> 9 | J8: =COUNTIFS(Raw_Data[country],"India",Raw_Data[satisfaction_score], 2) -> 21 | K8: =COUNTIFS(Raw_Data[country],"Kenya",Raw_Data[satisfaction_score], 2) -> 8 | L8: =COUNTIFS(Raw_Data[country],"Nepal",Raw_Data[satisfaction_score], 2) -> 5 | M8: =COUNTIFS(Raw_Data[country],"Nigeria",Raw_Data[satisfaction_score], 2) -> 15 | N8: =COUNTIFS(Raw_Data[country],"South Africa",Raw_Data[satisfaction_score], 2) -> 10 | O8: =COUNTIFS(Raw_Data[country],"United Kingdom",Raw_Data[satisfaction_score], 2) -> 21 | P8: =COUNTIFS(Raw_Data[country],"USA",Raw_Data[satisfaction_score], 2) -> 8
A9: Ghana | B9: 540 | C9: 27799 | D9: 295.72 | G9: 3 | H9: =COUNTIFS(Raw_Data[country],"Brazil",Raw_Data[satisfaction_score],3) -> 13 | I9: =COUNTIFS(Raw_Data[country],"Ghana",Raw_Data[satisfaction_score], 3) -> 21 | J9: =COUNTIFS(Raw_Data[country],"India",Raw_Data[satisfaction_score], 3) -> 34 | K9: =COUNTIFS(Raw_Data[country],"Kenya",Raw_Data[satisfaction_score], 3) -> 19 | L9: =COUNTIFS(Raw_Data[country],"Nepal",Raw_Data[satisfaction_score], 3) -> 12 | M9: =COUNTIFS(Raw_Data[country],"Nigeria",Raw_Data[satisfaction_score], 3) -> 27 | N9: =COUNTIFS(Raw_Data[country],"South Africa",Raw_Data[satisfaction_score], 3) -> 14 | O9: =COUNTIFS(Raw_Data[country],"United Kingdom",Raw_Data[satisfaction_score], 3) -> 62 | P9: =COUNTIFS(Raw_Data[country],"USA",Raw_Data[satisfaction_score], 3) -> 27
A10: Family | B10: 88.2 | C10: 5883 | D10: 73.93 | G10: 4 | H10: =COUNTIFS(Raw_Data[country],"Brazil",Raw_Data[satisfaction_score],4) -> 7 | I10: =COUNTIFS(Raw_Data[country],"Ghana",Raw_Data[satisfaction_score], 4) -> 9 | J10: =COUNTIFS(Raw_Data[country],"India",Raw_Data[satisfaction_score], 4) -> 24 | K10: =COUNTIFS(Raw_Data[country],"Kenya",Raw_Data[satisfaction_score], 4) -> 19 | L10: =COUNTIFS(Raw_Data[country],"Nepal",Raw_Data[satisfaction_score], 4) -> 15 | M10: =COUNTIFS(Raw_Data[country],"Nigeria",Raw_Data[satisfaction_score], 4) -> 6 | N10: =COUNTIFS(Raw_Data[country],"South Africa",Raw_Data[satisfaction_score], 4) -> 14 | O10: =COUNTIFS(Raw_Data[country],"United Kingdom",Raw_Data[satisfaction_score], 4) -> 43 | P10: =COUNTIFS(Raw_Data[country],"USA",Raw_Data[satisfaction_score], 4) -> 15
A11: Free | B11: 115.1 | C11: 6054 | D11: 0 | G11: 5 | H11: =COUNTIFS(Raw_Data[country],"Brazil",Raw_Data[satisfaction_score],5) -> 8 | I11: =COUNTIFS(Raw_Data[country],"Ghana",Raw_Data[satisfaction_score], 5) -> 9 | J11: =COUNTIFS(Raw_Data[country],"India",Raw_Data[satisfaction_score], 5) -> 14 | K11: =COUNTIFS(Raw_Data[country],"Kenya",Raw_Data[satisfaction_score], 5) -> 9 | L11: =COUNTIFS(Raw_Data[country],"Nepal",Raw_Data[satisfaction_score], 5) -> 4 | M11: =COUNTIFS(Raw_Data[country],"Nigeria",Raw_Data[satisfaction_score], 5) -> 6 | N11: =COUNTIFS(Raw_Data[country],"South Africa",Raw_Data[satisfaction_score], 5) -> 6 | O11: =COUNTIFS(Raw_Data[country],"United Kingdom",Raw_Data[satisfaction_score], 5) -> 27 | P11: =COUNTIFS(Raw_Data[country],"USA",Raw_Data[satisfaction_score], 5) -> 13
A12: Premium | B12: 154.6 | C12: 7965 | D12: 111.89 | G12: Total | H12: =SUM(H6:H11) -> 40 | I12: =SUM(I6:I11) -> 56 | J12: =SUM(J6:J11) -> 114 | K12: =SUM(K6:K11) -> 65 | L12: =SUM(L6:L11) -> 46 | M12: =SUM(M6:M11) -> 65 | N12: =SUM(N6:N11) -> 55 | O12: =SUM(O6:O11) -> 183 | P12: =SUM(P6:P11) -> 76 | Q12: =SUM(H12:P12) -> 700
A13: Student | B13: 182.1 | C13: 7897 | D13: 109.9
A14: India | B14: 1097.7 | C14: 56986 | D14: 726.29 | G14: Net Monthly Income per Customer | H14: =D4/H12 -> 7.06825 | I14: =D9/I12 -> 5.2807143 | J14: =D14/J12 -> 6.3709649 | K14: =D19/K12 -> 6.286 | L14: =D24/L12 -> 7.2541304 | M14: =D29/M12 -> 5.6870769 | N14: =D34/N12 -> 5.9581818 | O14: =D39/O12 -> 6.3327869 | P14: =D44/P12 -> 6.3097368
A15: Family | B15: 293.5 | C15: 16095 | D15: 241.77
A16: Free | B16: 127.7 | C16: 6465 | D16: 0
A17: Premium | B17: 332.1 | C17: 18080 | D17: 274.73 | G17: Churn
A18: Student | B18: 344.4 | C18: 16346 | D18: 209.79 | H18: =AVERAGEIFS(Raw_Data[[churned]:[churned]],Raw_Data[[country]:[country]],H4) -> 0.375 | I18: =AVERAGEIFS(Raw_Data[[churned]:[churned]],Raw_Data[[country]:[country]],I4) -> 0.375 | J18: =AVERAGEIFS(Raw_Data[[churned]:[churned]],Raw_Data[[country]:[country]],J4) -> 0.24561404 | K18: =AVERAGEIFS(Raw_Data[[churned]:[churned]],Raw_Data[[country]:[country]],K4) -> 0.32307692 | L18: =AVERAGEIFS(Raw_Data[[churned]:[churned]],Raw_Data[[country]:[country]],L4) -> 0.26086957 | M18: =AVERAGEIFS(Raw_Data[[churned]:[churned]],Raw_Data[[country]:[country]],M4) -> 0.38461538 | N18: =AVERAGEIFS(Raw_Data[[churned]:[churned]],Raw_Data[[country]:[country]],N4) -> 0.27272727 | O18: =AVERAGEIFS(Raw_Data[[churned]:[churned]],Raw_Data[[country]:[country]],O4) -> 0.32240437 | P18: =AVERAGEIFS(Raw_Data[[churned]:[churned]],Raw_Data[[country]:[country]],P4) -> 0.23684211
A19: Kenya | B19: 622 | C19: 32442 | D19: 408.59
A20: Family | B20: 232.7 | C20: 11908 | D20: 165.84
A21: Free | B21: 95.9 | C21: 4606 | D21: 0
A22: Premium | B22: 146.5 | C22: 8479 | D22: 124.87
A23: Student | B23: 146.9 | C23: 7449 | D23: 117.88
A24: Nepal | B24: 468.4 | C24: 22688 | D24: 333.69
A25: Family | B25: 194.6 | C25: 9390 | D25: 147.86
A26: Free | B26: 43.6 | C26: 2936 | D26: 0
A27: Premium | B27: 86.6 | C27: 4012 | D27: 83.92
A28: Student | B28: 143.6 | C28: 6350 | D28: 101.91
A29: Nigeria | B29: 646.2 | C29: 32505 | D29: 369.66
A30: Family | B30: 117.5 | C30: 7466 | D30: 87.92
... A49: Grand Total | B49: 7017.7 | C49: 349344 | D49: 4382.82
